<?xml version="1.0" ?>
<!-- =================================================================================== -->
<!-- |    This document was autogenerated by xacro from sentry.xacro                   | -->
<!-- |    EDITING THIS FILE BY HAND IS NOT RECOMMENDED                                 | -->
<!-- =================================================================================== -->
<robot name="sentry" xmlns:xacro="http://www.ros.org/wiki/xacro">
  <!-- define the base-link origin to lie at floor level, between the drive wheels-->
  <!--main body is a simple box; origin is a center of box-->
  <!--clearance from bottom of box to ground-->
  <!-- placement of main body relative to base link frame -->
  <!-- define the wheel dimensions-->
  <!-- "track" is the distance between the wheels -->
  <!-- spacing between wheels on the same side -->
  <!-- battery box dimensions -->
  <!-- placement of battery box relative to base frame -->
  <!--here is a default inertia matrix with small, but legal values; use this when don't need accuracy for I -->
  <!--model will assign inertia matrix dominated by main body box -->
  <!-- left = 1 if its the left wheel -1 if its the right wheel. displacement says how back/forward 
    the wheel is from the center-->
  <link name="base_link">
    <visual>
      <geometry>
        <box size="1.0 0.3 0.6"/>
      </geometry>
      <!--
            <origin xyz="${bodyOX} ${bodyOY} ${bodyOZ}" rpy="0 0 0"/>
            -->
      <origin rpy="0 0 0" xyz="0 0 0"/>
    </visual>
    <collision>
      <geometry>
        <box size="1.0 0.3 0.6"/>
      </geometry>
      <!--
            <origin xyz="${bodyOX} ${bodyOY} ${bodyOZ}" rpy="0 0 0"/>
            -->
      <origin rpy="0 0 0" xyz="0 0 0"/>
    </collision>
    <inertial>
      <!--assign almost all the mass to the main body box; set m= 100kg; treat I as approx m*r^2 -->
      <mass value="50"/>
      <inertia ixx="10" ixy="0" ixz="0" iyy="10" iyz="0" izz="10"/>
    </inertial>
  </link>
  <!-- front wheels -->
  <link name="left4_wheel">
    <visual>
      <geometry>
        <cylinder length="0.2" radius="0.1"/>
      </geometry>
    </visual>
    <collision>
      <geometry>
        <cylinder length="0.2" radius="0.1"/>
      </geometry>
    </collision>
    <inertial>
      <!--assign inertial properties to drive wheels -->
      <mass value="1"/>
      <inertia ixx="0.1" ixy="0" ixz="0" iyy="0.1" iyz="0" izz="0.1"/>
    </inertial>
  </link>
  <joint name="left4_wheel_joint" type="continuous">
    <axis xyz="0 0 1"/>
    <parent link="base_link"/>
    <child link="left4_wheel"/>
    <!--
            <origin xyz="0 ${left*track/2} ${tirerad}" rpy="0 ${M_PI/2} ${M_PI/2}"/>
            -->
    <origin rpy="0 1.57079632679 1.57079632679" xyz="0.5 0.26 -0.3"/>
    <limit effort="100" velocity="15"/>
    <joint_properties damping="0.0" friction="0.0"/>
  </joint>
  <link name="right4_wheel">
    <visual>
      <geometry>
        <cylinder length="0.2" radius="0.1"/>
      </geometry>
    </visual>
    <collision>
      <geometry>
        <cylinder length="0.2" radius="0.1"/>
      </geometry>
    </collision>
    <inertial>
      <!--assign inertial properties to drive wheels -->
      <mass value="1"/>
      <inertia ixx="0.1" ixy="0" ixz="0" iyy="0.1" iyz="0" izz="0.1"/>
    </inertial>
  </link>
  <joint name="right4_wheel_joint" type="continuous">
    <axis xyz="0 0 1"/>
    <parent link="base_link"/>
    <child link="right4_wheel"/>
    <!--
            <origin xyz="0 ${left*track/2} ${tirerad}" rpy="0 ${M_PI/2} ${M_PI/2}"/>
            -->
    <origin rpy="0 1.57079632679 1.57079632679" xyz="0.5 -0.26 -0.3"/>
    <limit effort="100" velocity="15"/>
    <joint_properties damping="0.0" friction="0.0"/>
  </joint>
  <link name="left3_wheel">
    <visual>
      <geometry>
        <cylinder length="0.2" radius="0.1"/>
      </geometry>
    </visual>
    <collision>
      <geometry>
        <cylinder length="0.2" radius="0.1"/>
      </geometry>
    </collision>
    <inertial>
      <!--assign inertial properties to drive wheels -->
      <mass value="1"/>
      <inertia ixx="0.1" ixy="0" ixz="0" iyy="0.1" iyz="0" izz="0.1"/>
    </inertial>
  </link>
  <joint name="left3_wheel_joint" type="continuous">
    <axis xyz="0 0 1"/>
    <parent link="base_link"/>
    <child link="left3_wheel"/>
    <!--
            <origin xyz="0 ${left*track/2} ${tirerad}" rpy="0 ${M_PI/2} ${M_PI/2}"/>
            -->
    <origin rpy="0 1.57079632679 1.57079632679" xyz="0.26 0.26 -0.3"/>
    <limit effort="100" velocity="15"/>
    <joint_properties damping="0.0" friction="0.0"/>
  </joint>
  <link name="right3_wheel">
    <visual>
      <geometry>
        <cylinder length="0.2" radius="0.1"/>
      </geometry>
    </visual>
    <collision>
      <geometry>
        <cylinder length="0.2" radius="0.1"/>
      </geometry>
    </collision>
    <inertial>
      <!--assign inertial properties to drive wheels -->
      <mass value="1"/>
      <inertia ixx="0.1" ixy="0" ixz="0" iyy="0.1" iyz="0" izz="0.1"/>
    </inertial>
  </link>
  <joint name="right3_wheel_joint" type="continuous">
    <axis xyz="0 0 1"/>
    <parent link="base_link"/>
    <child link="right3_wheel"/>
    <!--
            <origin xyz="0 ${left*track/2} ${tirerad}" rpy="0 ${M_PI/2} ${M_PI/2}"/>
            -->
    <origin rpy="0 1.57079632679 1.57079632679" xyz="0.26 -0.26 -0.3"/>
    <limit effort="100" velocity="15"/>
    <joint_properties damping="0.0" friction="0.0"/>
  </joint>
  <!-- center two wheels -->
  <link name="left2_wheel">
    <visual>
      <geometry>
        <cylinder length="0.2" radius="0.1"/>
      </geometry>
    </visual>
    <collision>
      <geometry>
        <cylinder length="0.2" radius="0.1"/>
      </geometry>
    </collision>
    <inertial>
      <!--assign inertial properties to drive wheels -->
      <mass value="1"/>
      <inertia ixx="0.1" ixy="0" ixz="0" iyy="0.1" iyz="0" izz="0.1"/>
    </inertial>
  </link>
  <joint name="left2_wheel_joint" type="continuous">
    <axis xyz="0 0 1"/>
    <parent link="base_link"/>
    <child link="left2_wheel"/>
    <!--
            <origin xyz="0 ${left*track/2} ${tirerad}" rpy="0 ${M_PI/2} ${M_PI/2}"/>
            -->
    <origin rpy="0 1.57079632679 1.57079632679" xyz="0 0.26 -0.3"/>
    <limit effort="100" velocity="15"/>
    <joint_properties damping="0.0" friction="0.0"/>
  </joint>
  <link name="right2_wheel">
    <visual>
      <geometry>
        <cylinder length="0.2" radius="0.1"/>
      </geometry>
    </visual>
    <collision>
      <geometry>
        <cylinder length="0.2" radius="0.1"/>
      </geometry>
    </collision>
    <inertial>
      <!--assign inertial properties to drive wheels -->
      <mass value="1"/>
      <inertia ixx="0.1" ixy="0" ixz="0" iyy="0.1" iyz="0" izz="0.1"/>
    </inertial>
  </link>
  <joint name="right2_wheel_joint" type="continuous">
    <axis xyz="0 0 1"/>
    <parent link="base_link"/>
    <child link="right2_wheel"/>
    <!--
            <origin xyz="0 ${left*track/2} ${tirerad}" rpy="0 ${M_PI/2} ${M_PI/2}"/>
            -->
    <origin rpy="0 1.57079632679 1.57079632679" xyz="0 -0.26 -0.3"/>
    <limit effort="100" velocity="15"/>
    <joint_properties damping="0.0" friction="0.0"/>
  </joint>
  <!-- rear wheels -->
  <link name="left1_wheel">
    <visual>
      <geometry>
        <cylinder length="0.2" radius="0.1"/>
      </geometry>
    </visual>
    <collision>
      <geometry>
        <cylinder length="0.2" radius="0.1"/>
      </geometry>
    </collision>
    <inertial>
      <!--assign inertial properties to drive wheels -->
      <mass value="1"/>
      <inertia ixx="0.1" ixy="0" ixz="0" iyy="0.1" iyz="0" izz="0.1"/>
    </inertial>
  </link>
  <joint name="left1_wheel_joint" type="continuous">
    <axis xyz="0 0 1"/>
    <parent link="base_link"/>
    <child link="left1_wheel"/>
    <!--
            <origin xyz="0 ${left*track/2} ${tirerad}" rpy="0 ${M_PI/2} ${M_PI/2}"/>
            -->
    <origin rpy="0 1.57079632679 1.57079632679" xyz="-0.3 0.26 -0.3"/>
    <limit effort="100" velocity="15"/>
    <joint_properties damping="0.0" friction="0.0"/>
  </joint>
  <link name="right1_wheel">
    <visual>
      <geometry>
        <cylinder length="0.2" radius="0.1"/>
      </geometry>
    </visual>
    <collision>
      <geometry>
        <cylinder length="0.2" radius="0.1"/>
      </geometry>
    </collision>
    <inertial>
      <!--assign inertial properties to drive wheels -->
      <mass value="1"/>
      <inertia ixx="0.1" ixy="0" ixz="0" iyy="0.1" iyz="0" izz="0.1"/>
    </inertial>
  </link>
  <joint name="right1_wheel_joint" type="continuous">
    <axis xyz="0 0 1"/>
    <parent link="base_link"/>
    <child link="right1_wheel"/>
    <!--
            <origin xyz="0 ${left*track/2} ${tirerad}" rpy="0 ${M_PI/2} ${M_PI/2}"/>
            -->
    <origin rpy="0 1.57079632679 1.57079632679" xyz="-0.3 -0.26 -0.3"/>
    <limit effort="100" velocity="15"/>
    <joint_properties damping="0.0" friction="0.0"/>
  </joint>
  <link name="left0_wheel">
    <visual>
      <geometry>
        <cylinder length="0.2" radius="0.1"/>
      </geometry>
    </visual>
    <collision>
      <geometry>
        <cylinder length="0.2" radius="0.1"/>
      </geometry>
    </collision>
    <inertial>
      <!--assign inertial properties to drive wheels -->
      <mass value="1"/>
      <inertia ixx="0.1" ixy="0" ixz="0" iyy="0.1" iyz="0" izz="0.1"/>
    </inertial>
  </link>
  <joint name="left0_wheel_joint" type="continuous">
    <axis xyz="0 0 1"/>
    <parent link="base_link"/>
    <child link="left0_wheel"/>
    <!--
            <origin xyz="0 ${left*track/2} ${tirerad}" rpy="0 ${M_PI/2} ${M_PI/2}"/>
            -->
    <origin rpy="0 1.57079632679 1.57079632679" xyz="-0.5 0.26 -0.3"/>
    <limit effort="100" velocity="15"/>
    <joint_properties damping="0.0" friction="0.0"/>
  </joint>
  <link name="right0_wheel">
    <visual>
      <geometry>
        <cylinder length="0.2" radius="0.1"/>
      </geometry>
    </visual>
    <collision>
      <geometry>
        <cylinder length="0.2" radius="0.1"/>
      </geometry>
    </collision>
    <inertial>
      <!--assign inertial properties to drive wheels -->
      <mass value="1"/>
      <inertia ixx="0.1" ixy="0" ixz="0" iyy="0.1" iyz="0" izz="0.1"/>
    </inertial>
  </link>
  <joint name="right0_wheel_joint" type="continuous">
    <axis xyz="0 0 1"/>
    <parent link="base_link"/>
    <child link="right0_wheel"/>
    <!--
            <origin xyz="0 ${left*track/2} ${tirerad}" rpy="0 ${M_PI/2} ${M_PI/2}"/>
            -->
    <origin rpy="0 1.57079632679 1.57079632679" xyz="-0.5 -0.26 -0.3"/>
    <limit effort="100" velocity="15"/>
    <joint_properties damping="0.0" friction="0.0"/>
  </joint>
  <!-- big wheels -->
  <link name="leftbig_big_wheel">
    <visual>
      <geometry>
        <cylinder length="0.2" radius="0.135"/>
      </geometry>
    </visual>
    <collision>
      <geometry>
        <cylinder length="0.2" radius="0.135"/>
      </geometry>
    </collision>
    <inertial>
      <!--assign inertial properties to drive wheels -->
      <mass value="1.5"/>
      <inertia ixx="0.1" ixy="0" ixz="0" iyy="0.1" iyz="0" izz="0.1"/>
    </inertial>
  </link>
  <joint name="leftbig_big_wheel_joint" type="continuous">
    <axis xyz="0 0 1"/>
    <parent link="base_link"/>
    <child link="leftbig_big_wheel"/>
    <origin rpy="0 1.57079632679 1.57079632679" xyz="-0.33125 0.26 0.135"/>
    <limit effort="100" velocity="15"/>
    <joint_properties damping="0.0" friction="0.0"/>
  </joint>
  <link name="rightbig_big_wheel">
    <visual>
      <geometry>
        <cylinder length="0.2" radius="0.135"/>
      </geometry>
    </visual>
    <collision>
      <geometry>
        <cylinder length="0.2" radius="0.135"/>
      </geometry>
    </collision>
    <inertial>
      <!--assign inertial properties to drive wheels -->
      <mass value="1.5"/>
      <inertia ixx="0.1" ixy="0" ixz="0" iyy="0.1" iyz="0" izz="0.1"/>
    </inertial>
  </link>
  <joint name="rightbig_big_wheel_joint" type="continuous">
    <axis xyz="0 0 1"/>
    <parent link="base_link"/>
    <child link="rightbig_big_wheel"/>
    <origin rpy="0 1.57079632679 1.57079632679" xyz="-0.33125 -0.26 0.135"/>
    <limit effort="100" velocity="15"/>
    <joint_properties damping="0.0" friction="0.0"/>
  </joint>
  <gazebo>
    <plugin filename="libgazebo_ros_diff_drive.so" name="differential_drive_controller">
      <alwaysOn>true</alwaysOn>
      <updateRate>100</updateRate>
      <leftJoint>right0_wheel_joint</leftJoint>
      <rightJoint>left0_wheel_joint</rightJoint>
      <wheelSeparation>0.52</wheelSeparation>
      <wheelDiameter>0.2</wheelDiameter>
      <torque>200</torque>
      <commandTopic>cmd_vel</commandTopic>
      <odometryTopic>odom</odometryTopic>
      <odometryFrame>odom</odometryFrame>
      <robotBaseFrame>base_link</robotBaseFrame>
      <publishWheelTF>true</publishWheelTF>
      <publishWheelJointState>true</publishWheelJointState>
    </plugin>
  </gazebo>
</robot>

